Workbook
Name AMO_PAT: '1_Hypothèses'!$C$20
Name AMO_SAL: '1_Hypothèses'!$C$21
Name BFR_N: '7_Bilan_Synthèse'!$E$60
Name BFR_NPLUS1: '7_Bilan_Synthèse'!$F$60
Name CA_DETAIL_RANGE: '3_Drivers_CA'!$R$41:$R$52
Name CA_TOTAL_NPLUS1: '3_Drivers_CA'!$R$53
Name CHARGES_PATRONALES: '5_Personnel_CNSS'!$L$23
Name CIMR_ACTIF: '1_Hypothèses'!$C$25
Name CIMR_PAT: '1_Hypothèses'!$C$23
Name CIMR_SAL: '1_Hypothèses'!$C$24
Name CM_PLANCHER: '1_Hypothèses'!$C$11
Name CNSS_PAT: '1_Hypothèses'!$C$18
Name CNSS_SAL: '1_Hypothèses'!$C$19
Name COUT_EMPLOYEUR_TOTAL: '5_Personnel_CNSS'!$M$23
Name DIO_CIBLE: '1_Hypothèses'!$C$36
Name DPO_CIBLE: '1_Hypothèses'!$C$35
Name DSO_CIBLE: '1_Hypothèses'!$C$34
Name DSO_NPLUS1: '7_Bilan_Synthèse'!$F$61
Name EBITDA_N: '6_CPC_Normalisé'!$E$71
Name EBITDA_NPLUS1: '6_CPC_Normalisé'!$F$71
Name EQUILIBRE_BILAN_NPLUS1: '7_Bilan_Synthèse'!$F$55
Name GEAR_NPLUS1: '7_Bilan_Synthèse'!$F$64
Name INFLATION: '1_Hypothèses'!$C$29
Name IS_DU_NPLUS1: '6_CPC_Normalisé'!$F$64
Name MASSE_SALARIALE_BRUTE: '5_Personnel_CNSS'!$G$23
Name PLAFOND_CNSS: '1_Hypothèses'!$C$17
Name RAI_NPLUS1: '6_CPC_Normalisé'!$F$59
Name RESULTAT_NET_N: '6_CPC_Normalisé'!$E$66
Name RESULTAT_NET_NM1: '6_CPC_Normalisé'!$D$66
Name RESULTAT_NET_NPLUS1: '6_CPC_Normalisé'!$F$66
Name REX_NPLUS1: '6_CPC_Normalisé'!$F$25
Name RNET_RANGE: '6_CPC_Normalisé'!$D$66:$F$66
Name SEUIL_MAD: '1_Hypothèses'!$C$37
Name SEUIL_PCT: '1_Hypothèses'!$C$38
Name TAUX_CM: '1_Hypothèses'!$C$10
Name TAUX_IS: '1_Hypothèses'!$C$9
Name TAXE_FORM: '1_Hypothèses'!$C$22
Name TOTAL_BILAN_NPLUS1: '7_Bilan_Synthèse'!$F$26
Name TOTAL_PASSIF_NPLUS1: '7_Bilan_Synthèse'!$F$53
Name VENTES_711: '6_CPC_Normalisé'!$F$7
Name VENTES_712: '6_CPC_Normalisé'!$F$8
Name WACC: '1_Hypothèses'!$C$32
Name ZBB_BUDGET_NPLUS1: '4_ZBB_Charges'!$H$28
Name ZBB_REEL_N: '4_ZBB_Charges'!$G$28
Name ZBB_REEL_NM1: '4_ZBB_Charges'!$F$28

Sheet 0_Sommaire
B1: OUTIL DE PILOTAGE BUDGÉTAIRE — GROUPE INDUSTRIE MAROC — EXERCICE N+1
B3: Référentiel : CGNC — Code Général de Normalisation Comptable
B4: Périmètre : 2 entités juridiques × 4 sites × 6 centres de coût
B5: Méthodologie : Driver-based (CA tonnage × prix) + Zero-Based Budgeting (charges externes)
B7: STRUCTURE DU CLASSEUR
B9: Onglet | C9: Description | D9: Type
B10: 0_Sommaire | C10: Navigation et présentation du modèle | D10: Présent
B11: 1_Hypothèses | C11: Paramètres groupe : taux IS, CNSS, AMO, inflation, taux d'actualisation | D11: Saisie
B12: 2_Dashboard | C12: Vue COMEX : KPI EBITDA, marge, RAG, waterfall RN N → RN N+1 | D12: Auto
B13: 3_Drivers_CA | C13: Modèle volumes×prix par ligne de production / site (comptes 711/712) | D13: Saisie+Calc
B14: 4_ZBB_Charges | C14: Justification ligne à ligne — comptes 613/614 (services extérieurs) | D14: Saisie+Calc
B15: 5_Personnel_CNSS | C15: Masse salariale, CNSS plafonnée, AMO, taxe formation, CIMR (compte 617) | D15: Saisie+Calc
B16: 6_CPC_Normalisé | C16: Compte de Produits et Charges modèle CGNC (Exploitation/Financier/NC) | D16: Auto
B17: 7_Bilan_Synthèse | C17: Bilan de synthèse — actif/passif + ratios BFR et endettement | D17: Auto
B18: 8_Reporting_3A | C18: Comparatif Réel N-1 vs Réel N estimé vs Budget N+1 — analyse d'écarts | D18: Auto
B19: 9_Mapping_CGNC | C19: Audit trail — correspondance comptes CGNC ↔ agrégats de gestion | D19: Référentiel
B20: 10_Heatmap_Ecarts | C20: Carte thermique des écarts par centre de coût × ligne budgétaire | D20: Auto
... B22: 12_PowerQuery_Doc | C22: Documentation des connecteurs Sage 100 / SAP Business One | D22: Doc
B24: CONVENTION DE COULEUR
B25: Bleu | C25: Saisie / hypothèse modifiable par l'utilisateur | D25: —
B26: Noir | C26: Formule de calcul interne à la feuille | D26: —
B27: Vert | C27: Lien inter-feuille (consolidation) | D27: —
B28: Violet/Or | C28: En-têtes et synthèses de présentation | D28: —
A31: Document Confidentiel — Direction Financière — © 2026

Sheet 1_Hypothèses
B1: HYPOTHÈSES GROUPE — EXERCICE N+1
B3: 1. FISCALITÉ MAROCAINE (Loi de Finances 2026)
B4: Paramètre | C4: Valeur | D4: Unité | E4: Référence / Commentaire
B5: Taux IS — tranche 0 à 300 kMAD | C5: 0.175 | D5: % | E5: Article 19 CGI — taux progressif convergent vers cible unifiée
B6: Taux IS — tranche 300 kMAD à 1 MMAD | C6: 0.2 | D6: % | E6: Article 19 CGI
B7: Taux IS — tranche 1 MMAD à 100 MMAD | C7: 0.2275 | D7: % | E7: Article 19 CGI — convergence loi 2023-2026
B8: Taux IS — tranche > 100 MMAD | C8: 0.34 | D8: % | E8: Article 19 CGI — taux marginal grands groupes
B9: Taux IS retenu pour le modèle | C9: 0.2275 | D9: % | E9: À ajuster selon la tranche de résultat fiscal effectif
B10: Cotisation Minimale — taux | C10: 0.0025 | D10: % | E10: Article 144 CGI — 0,25% du CA HT + produits accessoires
B11: Cotisation Minimale — plancher | C11: 3000 | D11: MAD | E11: Article 144 CGI — minimum de 3 000 MAD
B12: Taux TVA standard | C12: 0.2 | D12: % | E12: Article 98 CGI
B13: Taux TVA réduit (industrie) | C13: 0.1 | D13: % | E13: Selon nature des intrants — à vérifier ligne par ligne
B15: 2. CHARGES SOCIALES (CNSS / AMO / Formation / CIMR)
B16: Paramètre | C16: Valeur | D16: Unité | E16: Référence / Commentaire
B17: Plafond CNSS mensuel | C17: 6000 | D17: MAD | E17: Décret nº 2-22-687 — plafond en vigueur
B18: Cotisation CNSS — part patronale | C18: 0.0898 | D18: % | E18: Prestations à court et long terme
B19: Cotisation CNSS — part salariale | C19: 0.0448 | D19: % | E19: Prestations à court et long terme
B20: AMO — part patronale | C20: 0.0411 | D20: % | E20: Sans plafond — sur salaire brut
B21: AMO — part salariale | C21: 0.0226 | D21: % | E21: Sans plafond — sur salaire brut
B22: Taxe de formation professionnelle | C22: 0.016 | D22: % | E22: 1,6% du salaire brut — OFPPT
B23: CIMR — part patronale (optionnel) | C23: 0.06 | D23: % | E23: Selon politique de retraite complémentaire
B24: CIMR — part salariale (optionnel) | C24: 0.06 | D24: % | E24: Selon politique de retraite complémentaire
B25: Activer CIMR (1=oui / 0=non) | C25: 1 | D25: — | E25: Levier de modélisation
B27: 3. PARAMÈTRES MACROÉCONOMIQUES & FINANCIERS
B28: Paramètre | C28: Valeur | D28: Unité | E28: Référence / Commentaire
B29: Inflation prévisionnelle N+1 | C29: 0.025 | D29: % | E29: Bank Al-Maghrib — projection médiane
B30: Taux de change EUR/MAD (clôture) | C30: 11.05 | D30: MAD | E30: BAM cours de référence
B31: Taux de change USD/MAD (clôture) | C31: 10.2 | D31: MAD | E31: BAM cours de référence
B32: Coût moyen pondéré du capital (WACC) | C32: 0.095 | D32: % | E32: Hypothèse interne DAF
B33: Coût de la dette bancaire moyenne | C33: 0.058 | D33: % | E33: TMP + spread négocié
B34: DSO cible — délai de recouvrement | C34: 75 | D34: jours | E34: Loi 69-21 sur les délais de paiement
B35: DPO cible — délai fournisseurs | C35: 60 | D35: jours | E35: Politique groupe
B36: DIO cible — rotation des stocks | C36: 45 | D36: jours | E36: KPI industrie transformation
B37: Seuil d'écart matériel — montant | C37: 50000 | D37: MAD | E37: Déclenche commentaire de gestion obligatoire
B38: Seuil d'écart matériel — pourcentage | C38: 0.05 | D38: % | E38: Déclenche commentaire de gestion obligatoire
A41: Document Confidentiel — Direction Financière — © 2026

Sheet 2_Dashboard
B1: DASHBOARD COMEX — BUDGET N+1 — VUE BOARD
B3: Synthèse exécutive : KPI financiers, statuts RAG, waterfall RN N→N+1
B5: INDICATEURS CLÉS — N+1
B6: CA Groupe N+1 | D6: EBITDA | F6: Marge EBITDA
B7: =VENTES_711+VENTES_712 -> 178291572 | D7: =EBITDA_NPLUS1 -> -97108721 | F7: =IFERROR(EBITDA_NPLUS1/(VENTES_711+VENTES_712),0) -> -0.54466243
B8: Comptes 711+712 | D8: REX + Dotations | F8: EBITDA / CA
B10: Résultat Net | D10: BFR | F10: Gearing
B11: =RESULTAT_NET_NPLUS1 -> -1.0956445e+08 | D11: =BFR_NPLUS1 -> 41700000 | F11: =GEAR_NPLUS1 -> -0.20867679
B12: Bottom line | D12: AC - PC (hors trésorerie) | F12: Dettes fin / CP
B15: STATUTS RAG — RATIOS DE STRUCTURE
B16: Indicateur | C16: Valeur | D16: Cible | E16: Tolérance ± | F16: Statut | G16: Action recommandée
B17: DSO (recouvrement) | C17: =DSO_NPLUS1 -> 109.37141 | D17: =DSO_CIBLE -> 75 | E17: 15 | F17: =IF(C17<=D17+E17,"🟢 Vert",IF(C17<=D17+2*E17,"🟡 Ambre","🔴 Rouge")) -> 🔴 Rouge | G17: =IF(C17<=D17+E17,"Maintenir",IF(C17<=D17+2*E17,"Surveiller","Plan d''action requis")) -> Plan d''action requis
B18: Gearing | C18: =GEAR_NPLUS1 -> -0.20867679 | D18: 0.6 | E18: 0.15 | F18: =IF(C18<=D18+E18,"🟢 Vert",IF(C18<=D18+2*E18,"🟡 Ambre","🔴 Rouge")) -> 🟢 Vert | G18: =IF(C18<=D18+E18,"Maintenir",IF(C18<=D18+2*E18,"Surveiller","Plan d''action requis")) -> Maintenir
B19: Marge EBITDA | C19: =IFERROR(EBITDA_NPLUS1/(VENTES_711+VENTES_712),0) -> -0.54466243 | D19: 0.12 | E19: 0.03 | F19: =IF(C19<=D19+E19,"🟢 Vert",IF(C19<=D19+2*E19,"🟡 Ambre","🔴 Rouge")) -> 🟢 Vert | G19: =IF(C19>=D19-E19,"Maintenir",IF(C19>=D19-2*E19,"Surveiller","Plan d''action requis")) -> Plan d''action requis
B20: Croissance CA | C20: =IFERROR((VENTES_711+VENTES_712)/('6_CPC_Normalisé'!E6+'6_CPC_Normalisé'!E7)-1,0) -> -0.17073687 | D20: 0.08 | E20: 0.04 | F20: =IF(C20<=D20+E20,"🟢 Vert",IF(C20<=D20+2*E20,"🟡 Ambre","🔴 Rouge")) -> 🟢 Vert | G20: =IF(C20>=D20-E20,"Maintenir",IF(C20>=D20-2*E20,"Surveiller","Plan d''action requis")) -> Plan d''action requis
B21: Variation BFR | C21: =IFERROR(BFR_NPLUS1/BFR_N-1,0) -> 0.10058401 | D21: 0.03 | E21: 0.02 | F21: =IF(C21<=D21+E21,"🟢 Vert",IF(C21<=D21+2*E21,"🟡 Ambre","🔴 Rouge")) -> 🔴 Rouge | G21: =IF(C21<=D21+E21,"Maintenir",IF(C21<=D21+2*E21,"Surveiller","Plan d''action requis")) -> Plan d''action requis
B24: WATERFALL — PASSAGE DU RÉSULTAT NET N → RÉSULTAT NET N+1 (en MAD)
B25: Étape | C25: Type | D25: Valeur | E25: Cumul | G25: Variation % | H25: Commentaire
B26: RN N (départ) | C26: Départ | D26: =RESULTAT_NET_N -> 47501025 | E26: =D26 -> 47501025 | G26: Point de départ — Réel N estimé
B27: Effet CA (volume×prix) | C27: Δ+ | D27: =(VENTES_711+VENTES_712)-('6_CPC_Normalisé'!E6+'6_CPC_Normalisé'!E7) -> -36708428 | E27: =E26+D27 -> 10792597 | G27: Drivers tonnage × prix unitaire
B28: Effet achats consommés | C28: Δ- | D28: =-(('6_CPC_Normalisé'!F17+'6_CPC_Normalisé'!F18)-('6_CPC_Normalisé'!E17+'6_CPC_Normalisé'!E18)) -> -3276000 | E28: =E27+D28 -> 7516597 | G28: Comptes 611/612 — pression matières
B29: Effet charges externes (ZBB) | C29: Δ- | D29: =-(ZBB_BUDGET_NPLUS1-ZBB_REEL_N) -> -276000 | E29: =E28+D29 -> 7240597 | G29: Comptes 613/614 — discipline ZBB
B30: Effet masse salariale | C30: Δ- | D30: =-(COUT_EMPLOYEUR_TOTAL-31200000) -> -28484293 | E30: =E29+D30 -> -21243696 | G30: Compte 617 — recrutements N+1
B31: Effet financier net | C31: Δ± | D31: =-((('6_CPC_Normalisé'!F38+'6_CPC_Normalisé'!F39+'6_CPC_Normalisé'!F40+'6_CPC_Normalisé'!F41)-('6_CPC_Normalisé'!E38+'6_CPC_Normalisé'!E39+'6_CPC_Normalisé'!E40+'6_CPC_Normalisé'!E41))-(('6_CPC_Normalisé'!F31+'6_CPC_Normalisé'!F32+'6_CPC_Normalisé'!F33+'6_CPC_Normalisé'!F34)-('6_CPC_Normalisé'!E31+'6_CPC_Normalisé'!E32+'6_CPC_Normalisé'!E33+'6_CPC_Normalisé'!E34))) -> -50000 | E31: =E30+D31 -> -21293696 | G31: Comptes 631/733 — coût dette
B32: Effet impôt (IS) | C32: Δ- | D32: =-(IS_DU_NPLUS1-MAX(0,'6_CPC_Normalisé'!E54)*TAUX_IS) -> -445728.93 | E32: =E31+D32 -> -21739425 | G32: Article 19 + 144 CGI
B33: RN N+1 (arrivée) | C33: Arrivée | D33: =RESULTAT_NET_NPLUS1 -> -1.0956445e+08 | E33: =D33 -> -1.0956445e+08 | G33: Point d'arrivée — Budget N+1
A54: Document Confidentiel — Direction Financière — © 2026

Sheet 3_Drivers_CA
B1: DRIVERS CA — INDUSTRIE — VOLUMES (TONNES) × PRIX UNITAIRE — N+1
B3: Méthode : Driver-based — CA = Σ (tonnes × prix unitaire) par ligne de production / site / mois
B4: Ventilation comptes CGNC : 7111 (ventes locales) / 7112 (ventes export) — à raffiner selon plan comptable groupe
B6: BLOC 1 — VOLUMES PRÉVISIONNELS (TONNES)
B7: Entité | C7: Site | D7: Ligne produit | E7: Compte CGNC | F7: Janv | G7: Févr | H7: Mars | I7: Avr | J7: Mai | K7: Juin | L7: Juil | M7: Août | N7: Sept | O7: Oct | P7: Nov | Q7: Déc | R7: Total tonnes
B8: IND_CASA | C8: Casa-Aïn Sebaâ | D8: Ligne A — Acier transformé | E8: 7111 | F8: 0 | G8: 0 | H8: 0 | I8: 0 | J8: 0 | K8: 272 | L8: 225 | M8: 171 | N8: 266 | O8: 267 | P8: 268 | Q8: 273 | R8: =SUM(F8:Q8) -> 1742
B9: IND_CASA | C9: Casa-Aïn Sebaâ | D9: Ligne B — Profilés | E9: 7111 | F9: 0 | G9: 0 | H9: 0 | I9: 0 | J9: 0 | K9: 194 | L9: 160 | M9: 122 | N9: 198 | O9: 205 | P9: 194 | Q9: 189 | R9: =SUM(F9:Q9) -> 1262
B10: IND_CASA | C10: Casa-Aïn Sebaâ | D10: Ligne C — Tubes soudés | E10: 7111 | F10: 0 | G10: 0 | H10: 0 | I10: 0 | J10: 0 | K10: 0 | L10: 119 | M10: 97 | N10: 143 | O10: 157 | P10: 145 | Q10: 146 | R10: =SUM(F10:Q10) -> 807
B11: IND_CASA | C11: Casa-Bouskoura | D11: Ligne A — Acier transformé | E11: 7111 | F11: 0 | G11: 0 | H11: 0 | I11: 0 | J11: 0 | K11: 0 | L11: 211 | M11: 175 | N11: 256 | O11: 273 | P11: 264 | Q11: 267 | R11: =SUM(F11:Q11) -> 1446
B12: IND_CASA | C12: Casa-Bouskoura | D12: Ligne B — Profilés | E12: 7111 | F12: 0 | G12: 0 | H12: 0 | I12: 0 | J12: 0 | K12: 0 | L12: 158 | M12: 129 | N12: 186 | O12: 206 | P12: 191 | Q12: 193 | R12: =SUM(F12:Q12) -> 1063
B13: IND_CASA | C13: Casa-Bouskoura | D13: Ligne C — Tubes soudés | E13: 7111 | F13: 0 | G13: 0 | H13: 0 | I13: 0 | J13: 0 | K13: 147 | L13: 112 | M13: 91 | N13: 140 | O13: 146 | P13: 143 | Q13: 152 | R13: =SUM(F13:Q13) -> 931
B14: IND_TANGER | C14: Tanger-Free Zone | D14: Ligne A — Acier transformé | E14: 7112 | F14: 0 | G14: 0 | H14: 0 | I14: 0 | J14: 0 | K14: 267 | L14: 212 | M14: 174 | N14: 269 | O14: 274 | P14: 278 | Q14: 284 | R14: =SUM(F14:Q14) -> 1758
B15: IND_TANGER | C15: Tanger-Free Zone | D15: Ligne B — Profilés | E15: 7112 | F15: 0 | G15: 0 | H15: 0 | I15: 0 | J15: 0 | K15: 183 | L15: 149 | M15: 130 | N15: 197 | O15: 199 | P15: 189 | Q15: 193 | R15: =SUM(F15:Q15) -> 1240
B16: IND_TANGER | C16: Tanger-Free Zone | D16: Ligne C — Tubes soudés | E16: 7112 | F16: 0 | G16: 0 | H16: 0 | I16: 0 | J16: 0 | K16: 146 | L16: 118 | M16: 96 | N16: 139 | O16: 152 | P16: 141 | Q16: 145 | R16: =SUM(F16:Q16) -> 937
B17: IND_TANGER | C17: Tanger-Mghogha | D17: Ligne A — Acier transformé | E17: 7111 | F17: 241 | G17: 0 | H17: 0 | I17: 0 | J17: 899999 | K17: 259 | L17: 226 | M17: 185 | N17: 262 | O17: 284 | P17: 278 | Q17: 263 | R17: =SUM(F17:Q17) -> 901997
B18: IND_TANGER | C18: Tanger-Mghogha | D18: Ligne B — Profilés | E18: 7111 | F18: 178 | G18: 0 | H18: 0 | I18: 0 | J18: 0 | K18: 189 | L18: 148 | M18: 133 | N18: 199 | O18: 208 | P18: 194 | Q18: 187 | R18: =SUM(F18:Q18) -> 1436
B19: IND_TANGER | C19: Tanger-Mghogha | D19: Ligne C — Tubes soudés | E19: 7111 | F19: 134 | G19: 0 | H19: 0 | I19: 0 | J19: 0 | K19: 147 | L19: 119 | M19: 92 | N19: 142 | O19: 150 | P19: 143 | Q19: 151 | R19: =SUM(F19:Q19) -> 1078
B20: TOTAL GROUPE | F20: =SUM(F8:F19) -> 553 | G20: =SUM(G8:G19) -> 0 | H20: =SUM(H8:H19) -> 0 | I20: =SUM(I8:I19) -> 0 | J20: =SUM(J8:J19) -> 899999 | K20: =SUM(K8:K19) -> 1804 | L20: =SUM(L8:L19) -> 1957 | M20: =SUM(M8:M19) -> 1595 | ... R20: =SUM(R8:R19) -> 915697
B23: BLOC 2 — PRIX UNITAIRES MOYENS (MAD / TONNE)
B24: Entité | C24: Site | D24: Ligne produit | E24: Compte CGNC | F24: Janv | G24: Févr | H24: Mars | I24: Avr | J24: Mai | K24: Juin | L24: Juil | M24: Août | N24: Sept | O24: Oct | P24: Nov | Q24: Déc | R24: Prix moyen pondéré
B25: IND_CASA | C25: Casa-Aïn Sebaâ | D25: Ligne A — Acier transformé | E25: 7111 | F25: 9800 | G25: 9820 | H25: 9841 | I25: 9861 | J25: 9882 | K25: 9902 | L25: 9922 | M25: 9943 | N25: 9963 | O25: 9984 | P25: 10004 | Q25: 10025 | R25: =IFERROR(SUMPRODUCT(F25:Q25,F8:Q8)/SUM(F8:Q8),0) -> 9965.4592
B26: IND_CASA | C26: Casa-Aïn Sebaâ | D26: Ligne B — Profilés | E26: 7111 | F26: 11200 | G26: 11223 | H26: 11247 | I26: 11270 | J26: 11293 | K26: 11317 | L26: 11340 | M26: 11363 | N26: 11387 | O26: 11410 | P26: 11433 | Q26: 11457 | R26: =IFERROR(SUMPRODUCT(F26:Q26,F9:Q9)/SUM(F9:Q9),0) -> 11389.251
B27: IND_CASA | C27: Casa-Aïn Sebaâ | D27: Ligne C — Tubes soudés | E27: 7111 | F27: 13500 | G27: 13528 | H27: 13556 | I27: 13584 | J27: 13612 | K27: 13641 | L27: 13669 | M27: 13697 | N27: 13725 | O27: 13753 | P27: 13781 | Q27: 13809 | R27: =IFERROR(SUMPRODUCT(F27:Q27,F10:Q10)/SUM(F10:Q10),0) -> 13744.083
B28: IND_CASA | C28: Casa-Bouskoura | D28: Ligne A — Acier transformé | E28: 7111 | F28: 9800 | G28: 9820 | H28: 9841 | I28: 9861 | J28: 9882 | K28: 9902 | L28: 9922 | M28: 9943 | N28: 9963 | O28: 9984 | P28: 10004 | Q28: 10025 | R28: =IFERROR(SUMPRODUCT(F28:Q28,F11:Q11)/SUM(F11:Q11),0) -> 9977.4952
B29: IND_CASA | C29: Casa-Bouskoura | D29: Ligne B — Profilés | E29: 7111 | F29: 11200 | G29: 11223 | H29: 11247 | I29: 11270 | J29: 11293 | K29: 11317 | L29: 11340 | M29: 11363 | N29: 11387 | O29: 11410 | P29: 11433 | Q29: 11457 | R29: =IFERROR(SUMPRODUCT(F29:Q29,F12:Q12)/SUM(F12:Q12),0) -> 11402.533
B30: IND_CASA | C30: Casa-Bouskoura | D30: Ligne C — Tubes soudés | E30: 7111 | F30: 13500 | G30: 13528 | H30: 13556 | I30: 13584 | J30: 13612 | K30: 13641 | L30: 13669 | M30: 13697 | N30: 13725 | O30: 13753 | P30: 13781 | Q30: 13809 | R30: =IFERROR(SUMPRODUCT(F30:Q30,F13:Q13)/SUM(F13:Q13),0) -> 13728.97
B31: IND_TANGER | C31: Tanger-Free Zone | D31: Ligne A — Acier transformé | E31: 7112 | F31: 9800 | G31: 9820 | H31: 9841 | I31: 9861 | J31: 9882 | K31: 9902 | L31: 9922 | M31: 9943 | N31: 9963 | O31: 9984 | P31: 10004 | Q31: 10025 | R31: =IFERROR(SUMPRODUCT(F31:Q31,F14:Q14)/SUM(F14:Q14),0) -> 9966.5842
B32: IND_TANGER | C32: Tanger-Free Zone | D32: Ligne B — Profilés | E32: 7112 | F32: 11200 | G32: 11223 | H32: 11247 | I32: 11270 | J32: 11293 | K32: 11317 | L32: 11340 | M32: 11363 | N32: 11387 | O32: 11410 | P32: 11433 | Q32: 11457 | R32: =IFERROR(SUMPRODUCT(F32:Q32,F15:Q15)/SUM(F15:Q15),0) -> 11390.103
B33: IND_TANGER | C33: Tanger-Free Zone | D33: Ligne C — Tubes soudés | E33: 7112 | F33: 13500 | G33: 13528 | H33: 13556 | I33: 13584 | J33: 13612 | K33: 13641 | L33: 13669 | M33: 13697 | N33: 13725 | O33: 13753 | P33: 13781 | Q33: 13809 | R33: =IFERROR(SUMPRODUCT(F33:Q33,F16:Q16)/SUM(F16:Q16),0) -> 13727.958
B34: IND_TANGER | C34: Tanger-Mghogha | D34: Ligne A — Acier transformé | E34: 7111 | F34: 9800 | G34: 9820 | H34: 9841 | I34: 9861 | J34: 9882 | K34: 9902 | L34: 9922 | M34: 9943 | N34: 9963 | O34: 9984 | P34: 10004 | Q34: 10025 | R34: =IFERROR(SUMPRODUCT(F34:Q34,F17:Q17)/SUM(F17:Q17),0) -> 9882.1413
B35: IND_TANGER | C35: Tanger-Mghogha | D35: Ligne B — Profilés | E35: 7111 | F35: 11200 | G35: 11223 | H35: 11247 | I35: 11270 | J35: 11293 | K35: 11317 | L35: 11340 | M35: 11363 | N35: 11387 | O35: 11410 | P35: 11433 | Q35: 11457 | R35: =IFERROR(SUMPRODUCT(F35:Q35,F18:Q18)/SUM(F18:Q18),0) -> 11366.202
B36: IND_TANGER | C36: Tanger-Mghogha | D36: Ligne C — Tubes soudés | E36: 7111 | F36: 13500 | G36: 13528 | H36: 13556 | I36: 13584 | J36: 13612 | K36: 13641 | L36: 13669 | M36: 13697 | N36: 13725 | O36: 13753 | P36: 13781 | Q36: 13809 | R36: =IFERROR(SUMPRODUCT(F36:Q36,F19:Q19)/SUM(F19:Q19),0) -> 13700.096
B39: BLOC 3 — CHIFFRE D'AFFAIRES (MAD) = VOLUMES × PRIX
B40: Entité | C40: Site | D40: Ligne produit | E40: Compte CGNC | F40: Janv | G40: Févr | H40: Mars | I40: Avr | J40: Mai | K40: Juin | L40: Juil | M40: Août | N40: Sept | O40: Oct | P40: Nov | Q40: Déc | R40: Total CA N+1
B41: IND_CASA | C41: Casa-Aïn Sebaâ | D41: Ligne A — Acier transformé | E41: 7111 | F41: =IFERROR(F8*F25,0) -> 0 | G41: =IFERROR(G8*G25,0) -> 0 | H41: =IFERROR(H8*H25,0) -> 0 | I41: =IFERROR(I8*I25,0) -> 0 | J41: =IFERROR(J8*J25,0) -> 0 | K41: =IFERROR(K8*K25,0) -> 2693344 | L41: =IFERROR(L8*L25,0) -> 2232450 | M41: =IFERROR(M8*M25,0) -> 1700253 | ... Q41: =IFERROR(Q8*Q25,0) -> 2736825 | R41: =SUM(F41:Q41) -> 17359830
B42: IND_CASA | C42: Casa-Aïn Sebaâ | D42: Ligne B — Profilés | E42: 7111 | F42: =IFERROR(F9*F26,0) -> 0 | G42: =IFERROR(G9*G26,0) -> 0 | H42: =IFERROR(H9*H26,0) -> 0 | I42: =IFERROR(I9*I26,0) -> 0 | J42: =IFERROR(J9*J26,0) -> 0 | K42: =IFERROR(K9*K26,0) -> 2195498 | L42: =IFERROR(L9*L26,0) -> 1814400 | M42: =IFERROR(M9*M26,0) -> 1386286 | ... Q42: =IFERROR(Q9*Q26,0) -> 2165373 | R42: =SUM(F42:Q42) -> 14373235
B43: IND_CASA | C43: Casa-Aïn Sebaâ | D43: Ligne C — Tubes soudés | E43: 7111 | F43: =IFERROR(F10*F27,0) -> 0 | G43: =IFERROR(G10*G27,0) -> 0 | H43: =IFERROR(H10*H27,0) -> 0 | I43: =IFERROR(I10*I27,0) -> 0 | J43: =IFERROR(J10*J27,0) -> 0 | K43: =IFERROR(K10*K27,0) -> 0 | L43: =IFERROR(L10*L27,0) -> 1626611 | M43: =IFERROR(M10*M27,0) -> 1328609 | ... Q43: =IFERROR(Q10*Q27,0) -> 2016114 | R43: =SUM(F43:Q43) -> 11091475
B44: IND_CASA | C44: Casa-Bouskoura | D44: Ligne A — Acier transformé | E44: 7111 | F44: =IFERROR(F11*F28,0) -> 0 | G44: =IFERROR(G11*G28,0) -> 0 | H44: =IFERROR(H11*H28,0) -> 0 | I44: =IFERROR(I11*I28,0) -> 0 | J44: =IFERROR(J11*J28,0) -> 0 | K44: =IFERROR(K11*K28,0) -> 0 | L44: =IFERROR(L11*L28,0) -> 2093542 | M44: =IFERROR(M11*M28,0) -> 1740025 | ... Q44: =IFERROR(Q11*Q28,0) -> 2676675 | R44: =SUM(F44:Q44) -> 14427458
B45: IND_CASA | C45: Casa-Bouskoura | D45: Ligne B — Profilés | E45: 7111 | F45: =IFERROR(F12*F29,0) -> 0 | G45: =IFERROR(G12*G29,0) -> 0 | H45: =IFERROR(H12*H29,0) -> 0 | I45: =IFERROR(I12*I29,0) -> 0 | J45: =IFERROR(J12*J29,0) -> 0 | K45: =IFERROR(K12*K29,0) -> 0 | L45: =IFERROR(L12*L29,0) -> 1791720 | M45: =IFERROR(M12*M29,0) -> 1465827 | ... Q45: =IFERROR(Q12*Q29,0) -> 2211201 | R45: =SUM(F45:Q45) -> 12120893
B46: IND_CASA | C46: Casa-Bouskoura | D46: Ligne C — Tubes soudés | E46: 7111 | F46: =IFERROR(F13*F30,0) -> 0 | G46: =IFERROR(G13*G30,0) -> 0 | H46: =IFERROR(H13*H30,0) -> 0 | I46: =IFERROR(I13*I30,0) -> 0 | J46: =IFERROR(J13*J30,0) -> 0 | K46: =IFERROR(K13*K30,0) -> 2005227 | L46: =IFERROR(L13*L30,0) -> 1530928 | M46: =IFERROR(M13*M30,0) -> 1246427 | ... Q46: =IFERROR(Q13*Q30,0) -> 2098968 | R46: =SUM(F46:Q46) -> 12781671
...

Sheet 4_ZBB_Charges
B1: ZERO-BASED BUDGETING — CHARGES EXTERNES (CGNC 613/614)
B3: Méthode ZBB : chaque ligne doit être justifiée à partir de zéro — pas de reconduction automatique du réalisé N
B4: Comptes couverts : 6131 Loc. crédit-bail / 6132 Locations / 6133 Entretien et réparations / 6134 Primes assurance / 6135 Rémunérations intermédiaires / 6136 Honoraires / 6137 Études / 6141 Études et recherches / 6142 Transports / 6143 Déplacements & missions / 6144 Publicité / 6145 Frais postaux / 6146 Cotisations & dons / 6147 Services bancaires / 6148 Autres
B6: Compte CGNC | C6: Libellé poste | D6: Centre de coût | E6: Site | F6: Réel N-1 | G6: Réel N estimé | H6: Budget N+1 (ZBB) | I6: Var N+1 vs N | J6: % Var | K6: Justification ZBB obligatoire | L6: Validé par | M6: Date validation
B7: 6131 | C7: Crédit-bail machines de production | D7: Production | E7: Casa-Aïn Sebaâ | F7: 1200000 | G7: 1280000 | H7: 1300000 | I7: =H7-G7 -> 20000 | J7: =IFERROR((H7-G7)/G7,0) -> 0.015625 | K7: À renseigner — base zéro : driver, qty, prix unitaire, contrat de référence
B8: 6132 | C8: Location entrepôts logistique | D8: Logistique | E8: Casa-Bouskoura | F8: 850000 | G8: 890000 | H8: 920000 | I8: =H8-G8 -> 30000 | J8: =IFERROR((H8-G8)/G8,0) -> 0.033707865 | K8: À renseigner — base zéro : driver, qty, prix unitaire, contrat de référence
B9: 6132 | C9: Location locaux administratifs | D9: Admin/Finance | E9: Casa-Aïn Sebaâ | F9: 420000 | G9: 435000 | H9: 445000 | I9: =H9-G9 -> 10000 | J9: =IFERROR((H9-G9)/G9,0) -> 0.022988506 | K9: À renseigner — base zéro : driver, qty, prix unitaire, contrat de référence
B10: 6132 | C10: Location locaux Tanger | D10: Production | E10: Tanger-Free Zone | F10: 680000 | G10: 720000 | H10: 740000 | I10: =H10-G10 -> 20000 | J10: =IFERROR((H10-G10)/G10,0) -> 0.027777778 | K10: À renseigner — base zéro : driver, qty, prix unitaire, contrat de référence
B11: 6133 | C11: Entretien outillage industriel | D11: Maintenance | E11: Casa-Aïn Sebaâ | F11: 560000 | G11: 610000 | H11: 580000 | I11: =H11-G11 -> -30000 | J11: =IFERROR((H11-G11)/G11,0) -> -0.049180328 | K11: À renseigner — base zéro : driver, qty, prix unitaire, contrat de référence
B12: 6133 | C12: Entretien équipements Tanger | D12: Maintenance | E12: Tanger-Mghogha | F12: 390000 | G12: 430000 | H12: 445000 | I12: =H12-G12 -> 15000 | J12: =IFERROR((H12-G12)/G12,0) -> 0.034883721 | K12: À renseigner — base zéro : driver, qty, prix unitaire, contrat de référence
B13: 6134 | C13: Assurances multirisque industrielle | D13: Admin/Finance | E13: Casa-Aïn Sebaâ | F13: 280000 | G13: 295000 | H13: 310000 | I13: =H13-G13 -> 15000 | J13: =IFERROR((H13-G13)/G13,0) -> 0.050847458 | K13: À renseigner — base zéro : driver, qty, prix unitaire, contrat de référence
B14: 6134 | C14: Assurances flotte automobile | D14: Logistique | E14: Casa-Bouskoura | F14: 145000 | G14: 152000 | H14: 160000 | I14: =H14-G14 -> 8000 | J14: =IFERROR((H14-G14)/G14,0) -> 0.052631579 | K14: À renseigner — base zéro : driver, qty, prix unitaire, contrat de référence
B15: 6135 | C15: Commissions agents commerciaux | D15: Commercial | E15: Casa-Aïn Sebaâ | F15: 320000 | G15: 365000 | H15: 390000 | I15: =H15-G15 -> 25000 | J15: =IFERROR((H15-G15)/G15,0) -> 0.068493151 | K15: À renseigner — base zéro : driver, qty, prix unitaire, contrat de référence
B16: 6136 | C16: Honoraires expert-comptable | D16: Admin/Finance | E16: Casa-Aïn Sebaâ | F16: 95000 | G16: 98000 | H16: 102000 | I16: =H16-G16 -> 4000 | J16: =IFERROR((H16-G16)/G16,0) -> 0.040816327 | K16: À renseigner — base zéro : driver, qty, prix unitaire, contrat de référence
B17: 6136 | C17: Honoraires commissaire aux comptes | D17: Admin/Finance | E17: Casa-Aïn Sebaâ | F17: 120000 | G17: 125000 | H17: 130000 | I17: =H17-G17 -> 5000 | J17: =IFERROR((H17-G17)/G17,0) -> 0.04 | K17: À renseigner — base zéro : driver, qty, prix unitaire, contrat de référence
B18: 6136 | C18: Honoraires juridiques & fiscaux | D18: Admin/Finance | E18: Casa-Aïn Sebaâ | F18: 85000 | G18: 92000 | H18: 100000 | I18: =H18-G18 -> 8000 | J18: =IFERROR((H18-G18)/G18,0) -> 0.086956522 | K18: À renseigner — base zéro : driver, qty, prix unitaire, contrat de référence
... B27: 6148 | C27: Autres charges externes diverses | D27: Admin/Finance | E27: Casa-Aïn Sebaâ | F27: 95000 | G27: 102000 | H27: 110000 | I27: =H27-G27 -> 8000 | J27: =IFERROR((H27-G27)/G27,0) -> 0.078431373 | K27: À renseigner — base zéro : driver, qty, prix unitaire, contrat de référence
B28: TOTAL ZBB | F28: =SUM(F7:F27) -> 6973000 | G28: =SUM(G7:G27) -> 7480000 | H28: =SUM(H7:H27) -> 7756000 | I28: =H28-G28 -> 276000 | J28: =IFERROR((H28-G28)/G28,0) -> 0.036898396
B31: RÈGLE D'AUDIT : ÉCART MATÉRIEL = (|Δ MAD| > SEUIL_MAD) ET/OU (|%Δ| > SEUIL_PCT) → JUSTIFICATION OBLIGATOIRE
A33: Document Confidentiel — Direction Financière — © 2026

Sheet 5_Personnel_CNSS
B1: MASSE SALARIALE & CHARGES SOCIALES — COMPTE 617 (CGNC)
B3: Décomposition CGNC : 6171 Rémunérations du personnel / 6174 Charges sociales / 6176 Charges sociales diverses / 6177 Rémunérations exploitant
B4: Charges patronales calculées : CNSS plafonnée 6 000 MAD × 8,98% + AMO 4,11% (sans plafond) + Taxe formation 1,6% + CIMR 6% (si actif)
B6: Entité | C6: Site | D6: Centre de coût | E6: Effectif | F6: Salaire brut moyen mensuel | G6: Salaire brut annuel total | H6: CNSS patronale plafonnée | I6: AMO patronale | J6: Taxe formation | K6: CIMR patronale | L6: Total charges patronales | M6: Coût employeur total | N6: Compte CGNC
B7: IND_CASA | C7: Casa-Aïn Sebaâ | D7: Production | E7: 145 | F7: 6800 | G7: =E7*F7*12 -> 11832000 | H7: =MIN(F7,PLAFOND_CNSS)*E7*12*CNSS_PAT -> 937512 | I7: =G7*AMO_PAT -> 486295.2 | J7: =G7*TAXE_FORM -> 189312 | K7: =G7*CIMR_PAT*CIMR_ACTIF -> 709920 | L7: =SUM(H7:K7) -> 2323039.2 | M7: =G7+L7 -> 14155039 | N7: 6171/6174
B8: IND_CASA | C8: Casa-Aïn Sebaâ | D8: Maintenance | E8: 22 | F8: 8500 | G8: =E8*F8*12 -> 2244000 | H8: =MIN(F8,PLAFOND_CNSS)*E8*12*CNSS_PAT -> 142243.2 | I8: =G8*AMO_PAT -> 92228.4 | J8: =G8*TAXE_FORM -> 35904 | K8: =G8*CIMR_PAT*CIMR_ACTIF -> 134640 | L8: =SUM(H8:K8) -> 405015.6 | M8: =G8+L8 -> 2649015.6 | N8: 6171/6174
B9: IND_CASA | C9: Casa-Aïn Sebaâ | D9: Qualité | E9: 12 | F9: 9200 | G9: =E9*F9*12 -> 1324800 | H9: =MIN(F9,PLAFOND_CNSS)*E9*12*CNSS_PAT -> 77587.2 | I9: =G9*AMO_PAT -> 54449.28 | J9: =G9*TAXE_FORM -> 21196.8 | K9: =G9*CIMR_PAT*CIMR_ACTIF -> 79488 | L9: =SUM(H9:K9) -> 232721.28 | M9: =G9+L9 -> 1557521.3 | N9: 6171/6174
B10: IND_CASA | C10: Casa-Aïn Sebaâ | D10: Logistique | E10: 28 | F10: 5800 | G10: =E10*F10*12 -> 1948800 | H10: =MIN(F10,PLAFOND_CNSS)*E10*12*CNSS_PAT -> 175002.24 | I10: =G10*AMO_PAT -> 80095.68 | J10: =G10*TAXE_FORM -> 31180.8 | K10: =G10*CIMR_PAT*CIMR_ACTIF -> 116928 | L10: =SUM(H10:K10) -> 403206.72 | M10: =G10+L10 -> 2352006.7 | N10: 6171/6174
B11: IND_CASA | C11: Casa-Aïn Sebaâ | D11: Commercial | E11: 18 | F11: 12500 | G11: =E11*F11*12 -> 2700000 | H11: =MIN(F11,PLAFOND_CNSS)*E11*12*CNSS_PAT -> 116380.8 | I11: =G11*AMO_PAT -> 110970 | J11: =G11*TAXE_FORM -> 43200 | K11: =G11*CIMR_PAT*CIMR_ACTIF -> 162000 | L11: =SUM(H11:K11) -> 432550.8 | M11: =G11+L11 -> 3132550.8 | N11: 6171/6174
B12: IND_CASA | C12: Casa-Aïn Sebaâ | D12: Admin/Finance | E12: 24 | F12: 11000 | G12: =E12*F12*12 -> 3168000 | H12: =MIN(F12,PLAFOND_CNSS)*E12*12*CNSS_PAT -> 155174.4 | I12: =G12*AMO_PAT -> 130204.8 | J12: =G12*TAXE_FORM -> 50688 | K12: =G12*CIMR_PAT*CIMR_ACTIF -> 190080 | L12: =SUM(H12:K12) -> 526147.2 | M12: =G12+L12 -> 3694147.2 | N12: 6171/6174
B13: IND_CASA | C13: Casa-Bouskoura | D13: Logistique | E13: 35 | F13: 5500 | G13: =E13*F13*12 -> 2310000 | H13: =MIN(F13,PLAFOND_CNSS)*E13*12*CNSS_PAT -> 207438 | I13: =G13*AMO_PAT -> 94941 | J13: =G13*TAXE_FORM -> 36960 | K13: =G13*CIMR_PAT*CIMR_ACTIF -> 138600 | L13: =SUM(H13:K13) -> 477939 | M13: =G13+L13 -> 2787939 | N13: 6171/6174
B14: IND_CASA | C14: Casa-Bouskoura | D14: Production | E14: 62 | F14: 6500 | G14: =E14*F14*12 -> 4836000 | H14: =MIN(F14,PLAFOND_CNSS)*E14*12*CNSS_PAT -> 400867.2 | I14: =G14*AMO_PAT -> 198759.6 | J14: =G14*TAXE_FORM -> 77376 | K14: =G14*CIMR_PAT*CIMR_ACTIF -> 290160 | L14: =SUM(H14:K14) -> 967162.8 | M14: =G14+L14 -> 5803162.8 | N14: 6171/6174
B15: IND_TANGER | C15: Tanger-Free Zone | D15: Production | E15: 108 | F15: 6200 | G15: =E15*F15*12 -> 8035200 | H15: =MIN(F15,PLAFOND_CNSS)*E15*12*CNSS_PAT -> 698284.8 | I15: =G15*AMO_PAT -> 330246.72 | J15: =G15*TAXE_FORM -> 128563.2 | K15: =G15*CIMR_PAT*CIMR_ACTIF -> 482112 | L15: =SUM(H15:K15) -> 1639206.7 | M15: =G15+L15 -> 9674406.7 | N15: 6171/6174
B16: IND_TANGER | C16: Tanger-Free Zone | D16: Maintenance | E16: 18 | F16: 7800 | G16: =E16*F16*12 -> 1684800 | H16: =MIN(F16,PLAFOND_CNSS)*E16*12*CNSS_PAT -> 116380.8 | I16: =G16*AMO_PAT -> 69245.28 | J16: =G16*TAXE_FORM -> 26956.8 | K16: =G16*CIMR_PAT*CIMR_ACTIF -> 101088 | L16: =SUM(H16:K16) -> 313670.88 | M16: =G16+L16 -> 1998470.9 | N16: 6171/6174
B17: IND_TANGER | C17: Tanger-Free Zone | D17: Qualité | E17: 10 | F17: 8500 | G17: =E17*F17*12 -> 1020000 | H17: =MIN(F17,PLAFOND_CNSS)*E17*12*CNSS_PAT -> 64656 | I17: =G17*AMO_PAT -> 41922 | J17: =G17*TAXE_FORM -> 16320 | K17: =G17*CIMR_PAT*CIMR_ACTIF -> 61200 | L17: =SUM(H17:K17) -> 184098 | M17: =G17+L17 -> 1204098 | N17: 6171/6174
B18: IND_TANGER | C18: Tanger-Free Zone | D18: Logistique | E18: 25 | F18: 5400 | G18: =E18*F18*12 -> 1620000 | H18: =MIN(F18,PLAFOND_CNSS)*E18*12*CNSS_PAT -> 145476 | I18: =G18*AMO_PAT -> 66582 | J18: =G18*TAXE_FORM -> 25920 | K18: =G18*CIMR_PAT*CIMR_ACTIF -> 97200 | L18: =SUM(H18:K18) -> 335178 | M18: =G18+L18 -> 1955178 | N18: 6171/6174
... B22: IND_TANGER | C22: Tanger-Mghogha | D22: Maintenance | E22: 14 | F22: 7500 | G22: =E22*F22*12 -> 1260000 | H22: =MIN(F22,PLAFOND_CNSS)*E22*12*CNSS_PAT -> 90518.4 | I22: =G22*AMO_PAT -> 51786 | J22: =G22*TAXE_FORM -> 20160 | K22: =G22*CIMR_PAT*CIMR_ACTIF -> 75600 | L22: =SUM(H22:K22) -> 238064.4 | M22: =G22+L22 -> 1498064.4 | N22: 6171/6174
B23: TOTAL GROUPE | E23: =SUM(E7:E22) -> 589 | F23: =IFERROR(SUMPRODUCT(E7:E22,F7:F22)/E23,0) -> 7082.0034 | G23: =SUM(G7:G22) -> 50055600 | H23: =SUM(H7:H22) -> 3767181.8 | I23: =SUM(I7:I22) -> 2057285.2 | J23: =SUM(J7:J22) -> 800889.6 | K23: =SUM(K7:K22) -> 3003336 | L23: =SUM(L7:L22) -> 9628692.6 | M23: =SUM(M7:M22) -> 59684293
B26: SYNTHÈSE PAR CENTRE DE COÛT
B27: Centre de coût | C27: Effectif | D27: Coût employeur annuel | E27: % du total
B28: Production | C28: =SUMIF($D$7:$D$22,"Production",$E$7:$E$22) -> 363 | D28: =SUMIF($D$7:$D$22,"Production",$M$7:$M$22) -> 33803655 | E28: =IFERROR(D28/COUT_EMPLOYEUR_TOTAL,0) -> 0.5663744
B29: Maintenance | C29: =SUMIF($D$7:$D$22,"Maintenance",$E$7:$E$22) -> 54 | D29: =SUMIF($D$7:$D$22,"Maintenance",$M$7:$M$22) -> 6145550.9 | E29: =IFERROR(D29/COUT_EMPLOYEUR_TOTAL,0) -> 0.10296764
B30: Qualité | C30: =SUMIF($D$7:$D$22,"Qualité",$E$7:$E$22) -> 22 | D30: =SUMIF($D$7:$D$22,"Qualité",$M$7:$M$22) -> 2761619.3 | E30: =IFERROR(D30/COUT_EMPLOYEUR_TOTAL,0) -> 0.046270453
B31: Logistique | C31: =SUMIF($D$7:$D$22,"Logistique",$E$7:$E$22) -> 88 | D31: =SUMIF($D$7:$D$22,"Logistique",$M$7:$M$22) -> 7095123.7 | E31: =IFERROR(D31/COUT_EMPLOYEUR_TOTAL,0) -> 0.11887757
B32: Commercial | C32: =SUMIF($D$7:$D$22,"Commercial",$E$7:$E$22) -> 26 | D32: =SUMIF($D$7:$D$22,"Commercial",$M$7:$M$22) -> 4417554 | E32: =IFERROR(D32/COUT_EMPLOYEUR_TOTAL,0) -> 0.074015353
B33: Admin/Finance | C33: =SUMIF($D$7:$D$22,"Admin/Finance",$E$7:$E$22) -> 36 | D33: =SUMIF($D$7:$D$22,"Admin/Finance",$M$7:$M$22) -> 5460789.6 | E33: =IFERROR(D33/COUT_EMPLOYEUR_TOTAL,0) -> 0.091494585
A36: Document Confidentiel — Direction Financière — © 2026

Sheet 6_CPC_Normalisé
B1: COMPTE DE PRODUITS ET CHARGES — MODÈLE NORMALISÉ CGNC
B3: Présentation 3 niveaux : Exploitation / Financier / Non Courant — conforme CGNC
B5: Compte | C5: Libellé | D5: Réel N-1 | E5: Réel N estimé | F5: Budget N+1 | G5: Var N+1 vs N
C6: I — PRODUITS D'EXPLOITATION
B7: 711 | C7: Ventes de marchandises (en l'état) | D7: 195000000 | E7: 215000000 | F7: =SUMIF('3_Drivers_CA'!$E$41:$E$52,"7111",'3_Drivers_CA'!$R$41:$R$52) -> 133783492 | G7: =IFERROR((F7-E7)/E7,0) -> -0.3777512
B8: 712 | C8: Ventes de biens et services produits | D8: 85000000 | E8: 92000000 | F8: =SUMIF('3_Drivers_CA'!$E$41:$E$52,"7112",'3_Drivers_CA'!$R$41:$R$52) -> 44508080 | G8: =IFERROR((F8-E8)/E8,0) -> -0.51621652
B9: 713 | C9: Variation de stocks de produits | D9: 1200000 | E9: 1500000 | F9: 1800000 | G9: =IFERROR((F9-E9)/E9,0) -> 0.2
B10: 714 | C10: Immobilisations produites par l'entreprise | D10: 0 | E10: 0 | F10: 500000 | G10: =IFERROR((F10-E10)/E10,0) -> 0
B11: 718 | C11: Autres produits d'exploitation | D11: 850000 | E11: 920000 | F11: 950000 | G11: =IFERROR((F11-E11)/E11,0) -> 0.032608696
B12: 719 | C12: Reprises d'exploitation et transferts de charges | D12: 320000 | E12: 280000 | F12: 250000 | G12: =IFERROR((F12-E12)/E12,0) -> -0.10714286
B13: I | C13: TOTAL PRODUITS D'EXPLOITATION (I) | D13: =SUM(D7:D12) -> 282370000 | E13: =SUM(E7:E12) -> 309700000 | F13: =SUM(F7:F12) -> 181791572 | G13: =IFERROR((F13-E13)/E13,0) -> -0.41300752
C15: II — CHARGES D'EXPLOITATION
B16: 611 | C16: Achats revendus de marchandises | D16: 145000000 | E16: 158000000 | F16: 168000000 | G16: =IFERROR((F16-E16)/E16,0) -> 0.063291139
B17: 612 | C17: Achats consommés de matières et fournitures | D17: 35000000 | E17: 39000000 | F17: 42000000 | G17: =IFERROR((F17-E17)/E17,0) -> 0.076923077
B18: 613/614 | C18: Autres charges externes (ZBB) | D18: =ZBB_REEL_NM1 -> 6973000 | E18: =ZBB_REEL_N -> 7480000 | F18: =ZBB_BUDGET_NPLUS1 -> 7756000 | G18: =IFERROR((F18-E18)/E18,0) -> 0.036898396
B19: 616 | C19: Impôts et taxes | D19: 850000 | E19: 920000 | F19: 980000 | G19: =IFERROR((F19-E19)/E19,0) -> 0.065217391
B20: 617 | C20: Charges de personnel (compte 617) | D20: 28500000 | E20: 31200000 | F20: =COUT_EMPLOYEUR_TOTAL -> 59684293 | G20: =IFERROR((F20-E20)/E20,0) -> 0.9129581
B21: 618 | C21: Autres charges d'exploitation | D21: 420000 | E21: 450000 | F21: 480000 | G21: =IFERROR((F21-E21)/E21,0) -> 0.066666667
B22: 619 | C22: Dotations d'exploitation (amortissements, provisions) | D22: 8500000 | E22: 9200000 | F22: 9800000 | G22: =IFERROR((F22-E22)/E22,0) -> 0.065217391
B23: II | C23: TOTAL CHARGES D'EXPLOITATION (II) | D23: =SUM(D16:D22) -> 225243000 | E23: =SUM(E16:E22) -> 246250000 | F23: =SUM(F16:F22) -> 2.8870029e+08 | G23: =IFERROR((F23-E23)/E23,0) -> 0.17238698
B25: III | C25: RÉSULTAT D'EXPLOITATION (I-II) | D25: =D13-D23 -> 57127000 | E25: =E13-E23 -> 63450000 | F25: =F13-F23 -> -1.0690872e+08 | G25: =IFERROR((F25-E25)/E25,0) -> -2.6849286
C27: IV — PRODUITS FINANCIERS
B28: 732 | C28: Produits des titres de participation | D28: 0 | E28: 0 | F28: 0 | G28: =IFERROR((F28-E28)/E28,0) -> 0
B29: 733 | C29: Gains de change | D29: 280000 | E29: 320000 | F29: 350000 | G29: =IFERROR((F29-E29)/E29,0) -> 0.09375
B30: 738 | C30: Intérêts et autres produits financiers | D30: 145000 | E30: 160000 | F30: 175000 | G30: =IFERROR((F30-E30)/E30,0) -> 0.09375
B31: 739 | C31: Reprises financières et transferts de charges | D31: 50000 | E31: 0 | F31: 0 | G31: =IFERROR((F31-E31)/E31,0) -> 0
B32: IV | C32: TOTAL PRODUITS FINANCIERS (IV) | D32: =SUM(D28:D31) -> 475000 | E32: =SUM(E28:E31) -> 480000 | F32: =SUM(F28:F31) -> 525000 | G32: =IFERROR((F32-E32)/E32,0) -> 0.09375
C34: V — CHARGES FINANCIÈRES
B35: 631 | C35: Charges d'intérêts | D35: 1850000 | E35: 2050000 | F35: 2200000 | G35: =IFERROR((F35-E35)/E35,0) -> 0.073170732
B36: 633 | C36: Pertes de change | D36: 320000 | E36: 380000 | F36: 400000 | G36: =IFERROR((F36-E36)/E36,0) -> 0.052631579
B37: 638 | C37: Autres charges financières | D37: 75000 | E37: 80000 | F37: 85000 | G37: =IFERROR((F37-E37)/E37,0) -> 0.0625
B38: 639 | C38: Dotations financières | D38: 0 | E38: 0 | F38: 50000 | G38: =IFERROR((F38-E38)/E38,0) -> 0
B39: V | C39: TOTAL CHARGES FINANCIÈRES (V) | D39: =SUM(D35:D38) -> 2245000 | E39: =SUM(E35:E38) -> 2510000 | F39: =SUM(F35:F38) -> 2735000 | G39: =IFERROR((F39-E39)/E39,0) -> 0.089641434
B41: VI | C41: RÉSULTAT FINANCIER (IV-V) | D41: =D32-D39 -> -1770000 | E41: =E32-E39 -> -2030000 | F41: =F32-F39 -> -2210000 | G41: =IFERROR((F41-E41)/E41,0) -> 0.088669951
B43: VII | C43: RÉSULTAT COURANT (III+VI) | D43: =D25+D41 -> 55357000 | E43: =E25+E41 -> 61420000 | F43: =F25+F41 -> -1.0911872e+08 | G43: =IFERROR((F43-E43)/E43,0) -> -2.7765992
C45: VIII — PRODUITS NON COURANTS
B46: 751 | C46: Produits de cession d'immobilisations | D46: 0 | E46: 250000 | F46: 0 | G46: =IFERROR((F46-E46)/E46,0) -> -1
B47: 756 | C47: Subventions d'équilibre | D47: 0 | E47: 0 | F47: 0 | G47: =IFERROR((F47-E47)/E47,0) -> 0
B48: 758 | C48: Autres produits non courants | D48: 0 | E48: 0 | F48: 0 | G48: =IFERROR((F48-E48)/E48,0) -> 0
B49: VIII | C49: TOTAL PRODUITS NON COURANTS (VIII) | D49: =SUM(D46:D48) -> 0 | E49: =SUM(E46:E48) -> 250000 | F49: =SUM(F46:F48) -> 0 | G49: =IFERROR((F49-E49)/E49,0) -> -1
...

Sheet 7_Bilan_Synthèse
B1: BILAN DE SYNTHÈSE — MODÈLE NORMALISÉ CGNC
B3: Présentation Actif / Passif — focus sur les agrégats BFR et endettement
B5: Compte | C5: Libellé | D5: Réel N-1 | E5: Réel N estimé | F5: Budget N+1
C6: ACTIF — IMMOBILISÉ
B7: 21 | C7: Immobilisations en non-valeurs (frais préliminaires) | D7: 450000 | E7: 380000 | F7: 320000
B8: 22 | C8: Immobilisations incorporelles (logiciels, fonds) | D8: 1200000 | E8: 1450000 | F8: 1700000
B9: 23 | C9: Immobilisations corporelles (terrains, bâtiments, ITM) | D9: 95000000 | E9: 102000000 | F9: 105000000
B10: 24/25 | C10: Immobilisations financières (titres, prêts) | D10: 3500000 | E10: 3500000 | F10: 3500000
B11: 27 | C11: Écarts de conversion - Actif | D11: 0 | E11: 0 | F11: 0
B12: I | C12: TOTAL ACTIF IMMOBILISÉ | D12: =SUM(D7:D11) -> 100150000 | E12: =SUM(E7:E11) -> 107330000 | F12: =SUM(F7:F11) -> 110520000
C14: ACTIF — CIRCULANT
B15: 31 | C15: Stocks (matières, encours, produits) | D15: 18500000 | E15: 19800000 | F15: 19500000
B16: 342 | C16: Clients et comptes rattachés | D16: 58000000 | E16: 62000000 | F16: 65000000
B17: 345 | C17: État (TVA, IS) - débiteur | D17: 4200000 | E17: 3800000 | F17: 3500000
B18: 348 | C18: Autres débiteurs et comptes de régularisation | D18: 1500000 | E18: 1650000 | F18: 1700000
B19: II | C19: TOTAL ACTIF CIRCULANT | D19: =SUM(D15:D18) -> 82200000 | E19: =SUM(E15:E18) -> 87250000 | F19: =SUM(F15:F18) -> 89700000
C21: TRÉSORERIE — ACTIF
B22: 514 | C22: Banques, TG et CCP | D22: 8500000 | E22: 9200000 | F22: 11500000
B23: 516 | C23: Caisses, régies d'avances | D23: 120000 | E23: 110000 | F23: 120000
B24: III | C24: TOTAL TRÉSORERIE - ACTIF | D24: =SUM(D22:D23) -> 8620000 | E24: =SUM(E22:E23) -> 9310000 | F24: =SUM(F22:F23) -> 11620000
B26: ACTIF | C26: TOTAL ACTIF (I+II+III) | D26: =D12+D19+D24 -> 190970000 | E26: =E12+E19+E24 -> 203890000 | F26: =F12+F19+F24 -> 211840000
C29: PASSIF — FINANCEMENT PERMANENT
B30: 111 | C30: Capital social | D30: 50000000 | E30: 50000000 | F30: 50000000
B31: 112 | C31: Primes d'émission, fusion, apport | D31: 8000000 | E31: 8000000 | F31: 8000000
B32: 114 | C32: Réserves légales et réglementées | D32: 5000000 | E32: 5000000 | F32: 5000000
B33: 116 | C33: Report à nouveau | D33: 12500000 | E33: 18200000 | F33: 25000000
B34: 118 | C34: Résultat net de l'exercice | D34: =RESULTAT_NET_NM1 -> 42724658 | E34: =RESULTAT_NET_N -> 47501025 | F34: =RESULTAT_NET_NPLUS1 -> -1.0956445e+08
B35: 13 | C35: Capitaux propres assimilés (subventions, provisions régl.) | D35: 1500000 | E35: 1400000 | F35: 1300000
B36: 14 | C36: Dettes de financement (emprunts > 1 an) | D36: 17790684 | E36: 17277950 | F36: 51766208
B37: 15 | C37: Provisions durables pour risques et charges | D37: 2200000 | E37: 2400000 | F37: 2600000
B38: I | C38: TOTAL FINANCEMENT PERMANENT | D38: =SUM(D30:D37) -> 1.3971534e+08 | E38: =SUM(E30:E37) -> 149778975 | F38: =SUM(F30:F37) -> 34101758
C40: PASSIF — CIRCULANT
B41: 441 | C41: Fournisseurs et comptes rattachés | D41: 32000000 | E41: 35500000 | F41: 38000000
B42: 443 | C42: Personnel - créditeur | D42: 2200000 | E42: 2400000 | F42: 2600000
B43: 444 | C43: Organismes sociaux (CNSS, AMO, CIMR) | D43: 1850000 | E43: 2050000 | F43: 2200000
B44: 445 | C44: État (TVA, IS) - créditeur | D44: 3200000 | E44: 3500000 | F44: 3800000
B45: 448 | C45: Autres créanciers et comptes de régularisation | D45: 6304658 | E45: 5911025 | F45: 1400000
B46: II | C46: TOTAL PASSIF CIRCULANT | D46: =SUM(D41:D45) -> 45554658 | E46: =SUM(E41:E45) -> 49361025 | F46: =SUM(F41:F45) -> 48000000
C48: TRÉSORERIE — PASSIF
B49: 552 | C49: Crédits de trésorerie (escompte, Spot) | D49: 4500000 | E49: 3800000 | F49: 2500000
...

Sheet 8_Reporting_3A
B1: REPORTING COMPARATIF — RÉEL N-1 / RÉEL N ESTIMÉ / BUDGET N+1
B3: Analyse d'écarts multi-axes : croissance, volume, prix, mix, productivité
B5: Code | C5: Agrégat / KPI | D5: Réel N-1 | E5: Réel N estimé | F5: Budget N+1 | G5: Δ N+1 vs N (MAD) | H5: Δ N+1 vs N (%) | I5: Statut RAG
B6: CA | C6: Chiffre d'affaires (711+712) | D6: ='6_CPC_Normalisé'!D6+'6_CPC_Normalisé'!D7 -> 195000000 | E6: ='6_CPC_Normalisé'!E6+'6_CPC_Normalisé'!E7 -> 215000000 | F6: =VENTES_711+VENTES_712 -> 178291572 | G6: =F6-E6 -> -36708428 | H6: =IFERROR((F6-E6)/ABS(E6),0) -> -0.17073687 | I6: =IF(H6>SEUIL_PCT,"🟢 Vert",IF(H6<-SEUIL_PCT,"🔴 Rouge","🟡 Ambre")) -> 🔴 Rouge
B7: MB | C7: Marge brute sur achats consommés | D7: =('6_CPC_Normalisé'!D6+'6_CPC_Normalisé'!D7)-('6_CPC_Normalisé'!D17+'6_CPC_Normalisé'!D18) -> 153027000 | E7: =('6_CPC_Normalisé'!E6+'6_CPC_Normalisé'!E7)-('6_CPC_Normalisé'!E17+'6_CPC_Normalisé'!E18) -> 168520000 | F7: =('6_CPC_Normalisé'!F6+'6_CPC_Normalisé'!F7)-('6_CPC_Normalisé'!F17+'6_CPC_Normalisé'!F18) -> 84027492 | G7: =F7-E7 -> -84492508 | H7: =IFERROR((F7-E7)/ABS(E7),0) -> -0.50137971 | I7: =IF(H7>SEUIL_PCT,"🟢 Vert",IF(H7<-SEUIL_PCT,"🔴 Rouge","🟡 Ambre")) -> 🔴 Rouge
B8: EBITDA | C8: EBITDA | D8: 0 | E8: =EBITDA_N -> 72650000 | F8: =EBITDA_NPLUS1 -> -97108721 | G8: =F8-E8 -> -1.6975872e+08 | H8: =IFERROR((F8-E8)/ABS(E8),0) -> -2.3366651 | I8: =IF(H8>SEUIL_PCT,"🟢 Vert",IF(H8<-SEUIL_PCT,"🔴 Rouge","🟡 Ambre")) -> 🔴 Rouge
B9: REX | C9: Résultat d'Exploitation | D9: 0 | E9: 0 | F9: =REX_NPLUS1 -> -1.0690872e+08 | G9: =F9-E9 -> -1.0690872e+08 | H9: =IFERROR((F9-E9)/ABS(E9),0) -> 0 | I9: =IF(H9>SEUIL_PCT,"🟢 Vert",IF(H9<-SEUIL_PCT,"🔴 Rouge","🟡 Ambre")) -> 🟡 Ambre
B10: RN | C10: Résultat Net | D10: =RESULTAT_NET_NM1 -> 42724658 | E10: =RESULTAT_NET_N -> 47501025 | F10: =RESULTAT_NET_NPLUS1 -> -1.0956445e+08 | G10: =F10-E10 -> -1.5706547e+08 | H10: =IFERROR((F10-E10)/ABS(E10),0) -> -3.3065702 | I10: =IF(H10>SEUIL_PCT,"🟢 Vert",IF(H10<-SEUIL_PCT,"🔴 Rouge","🟡 Ambre")) -> 🔴 Rouge
B11: Charges Pers | C11: Charges de personnel | D11: 28500000 | E11: 31200000 | F11: =COUT_EMPLOYEUR_TOTAL -> 59684293 | G11: =F11-E11 -> 28484293 | H11: =IFERROR((F11-E11)/ABS(E11),0) -> 0.9129581 | I11: =IF(H11<-SEUIL_PCT,"🟢 Vert",IF(H11>SEUIL_PCT,"🔴 Rouge","🟡 Ambre")) -> 🔴 Rouge
B12: Charges ext | C12: Autres charges externes (ZBB) | D12: =ZBB_REEL_NM1 -> 6973000 | E12: =ZBB_REEL_N -> 7480000 | F12: =ZBB_BUDGET_NPLUS1 -> 7756000 | G12: =F12-E12 -> 276000 | H12: =IFERROR((F12-E12)/ABS(E12),0) -> 0.036898396 | I12: =IF(H12<-SEUIL_PCT,"🟢 Vert",IF(H12>SEUIL_PCT,"🔴 Rouge","🟡 Ambre")) -> 🟡 Ambre
B13: BFR | C13: Besoin en Fonds de Roulement | D13: 0 | E13: =BFR_N -> 37888975 | F13: =BFR_NPLUS1 -> 41700000 | G13: =F13-E13 -> 3811025 | H13: =IFERROR((F13-E13)/ABS(E13),0) -> 0.10058401 | I13: =IF(H13<-SEUIL_PCT,"🟢 Vert",IF(H13>SEUIL_PCT,"🔴 Rouge","🟡 Ambre")) -> 🔴 Rouge
B14: DSO | C14: DSO (jours) | D14: 0 | E14: 0 | F14: =DSO_NPLUS1 -> 109.37141 | G14: =F14-E14 -> 109.37141 | H14: =IFERROR((F14-E14)/ABS(E14),0) -> 0 | I14: =IF(H14<-SEUIL_PCT,"🟢 Vert",IF(H14>SEUIL_PCT,"🔴 Rouge","🟡 Ambre")) -> 🟡 Ambre
B15: Gearing | C15: Gearing (Dettes / Capitaux propres) | D15: 0 | E15: 0 | F15: =GEAR_NPLUS1 -> -0.20867679 | G15: =F15-E15 -> -0.20867679 | H15: =IFERROR((F15-E15)/ABS(E15),0) -> 0 | I15: =IF(H15<-SEUIL_PCT,"🟢 Vert",IF(H15>SEUIL_PCT,"🔴 Rouge","🟡 Ambre")) -> 🟡 Ambre
B16: Total bilan | C16: Total bilan | D16: 0 | E16: 0 | F16: =TOTAL_BILAN_NPLUS1 -> 211840000 | G16: =F16-E16 -> 211840000 | H16: =IFERROR((F16-E16)/ABS(E16),0) -> 0 | I16: =IF(H16>SEUIL_PCT,"🟢 Vert",IF(H16<-SEUIL_PCT,"🔴 Rouge","🟡 Ambre")) -> 🟡 Ambre
A20: Document Confidentiel — Direction Financière — © 2026

Sheet 9_Mapping_CGNC
B1: MAPPING CGNC — TABLE DE CORRESPONDANCE COMPTES ↔ AGRÉGATS DE GESTION (AUDIT TRAIL)
B3: Référentiel : Plan Comptable Marocain — classes 1 à 7
B5: Compte CGNC | C5: Libellé compte | D5: Classe | E5: Agrégat de gestion | F5: Onglet source | G5: Logique de calcul
B6: 1111 | C6: Capital social | D6: 1 - Financement permanent | E6: Capitaux propres | F6: 7_Bilan_Synthèse | G6: Saisie directe
B7: 1140 | C7: Réserves légales et statutaires | D7: 1 | E7: Capitaux propres | F7: 7_Bilan_Synthèse | G7: Saisie + affectation RN
B8: 1161 | C8: Report à nouveau | D8: 1 | E8: Capitaux propres | F8: 7_Bilan_Synthèse | G8: RAN N-1 + (RN N - dividendes)
B9: 1181 | C9: Résultat net de l'exercice | D9: 1 | E9: Capitaux propres | F9: 7_Bilan_Synthèse | G9: Lien dynamique vers CPC ligne XIII
B10: 1410 | C10: Emprunts obligataires | D10: 1 | E10: Dettes financement | F10: 7_Bilan_Synthèse | G10: Saisie + tableau d'amortissement
B11: 1481 | C11: Emprunts auprès des établissements de crédit | D11: 1 | E11: Dettes financement | F11: 7_Bilan_Synthèse | G11: Saisie
B12: 1510 | C12: Provisions durables pour risques | D12: 1 | E12: Provisions | F12: 7_Bilan_Synthèse | G12: Saisie - mouvements de l'exercice
B13: 2111 | C13: Frais de constitution | D13: 2 - Actif immobilisé | E13: Immo non-valeurs | F13: 7_Bilan_Synthèse | G13: Amortis sur 5 ans
B14: 2230 | C14: Brevets, marques, logiciels | D14: 2 | E14: Immo incorporelles | F14: 7_Bilan_Synthèse | G14: Saisie + dotations
B15: 2311 | C15: Terrains nus | D15: 2 | E15: Immo corporelles | F15: 7_Bilan_Synthèse | G15: Saisie - non amortissable
B16: 2321 | C16: Bâtiments industriels | D16: 2 | E16: Immo corporelles | F16: 7_Bilan_Synthèse | G16: Saisie + dotations 4-5%
... B65: 7510 | C65: Produits de cession d'immobilisations | D65: 7 | E65: Produits non courants | F65: 6_CPC_Normalisé | G65: Cessions de l'exercice
A68: Document Confidentiel — Direction Financière — © 2026

Sheet 10_Heatmap_Ecarts
B1: HEATMAP — ÉCARTS BUDGÉTAIRES PAR CENTRE DE COÛT × COMPTE CGNC
B3: Lecture : écart Budget N+1 vs Réel N estimé en MAD — coloration thermique automatique
B5: Compte CGNC / Poste | C5: Production | D5: Maintenance | E5: Qualité | F5: Logistique | G5: Commercial | H5: Admin/Finance | I5: Total
B6: 6131 | C6: =IFERROR(SUMIFS('4_ZBB_Charges'!$H:$H,'4_ZBB_Charges'!$B:$B,"6131",'4_ZBB_Charges'!$D:$D,"Production")-SUMIFS('4_ZBB_Charges'!$G:$G,'4_ZBB_Charges'!$B:$B,"6131",'4_ZBB_Charges'!$D:$D,"Production"),0) -> 20000 | D6: =IFERROR(SUMIFS('4_ZBB_Charges'!$H:$H,'4_ZBB_Charges'!$B:$B,"6131",'4_ZBB_Charges'!$D:$D,"Maintenance")-SUMIFS('4_ZBB_Charges'!$G:$G,'4_ZBB_Charges'!$B:$B,"6131",'4_ZBB_Charges'!$D:$D,"Maintenance"),0) -> 0 | E6: =IFERROR(SUMIFS('4_ZBB_Charges'!$H:$H,'4_ZBB_Charges'!$B:$B,"6131",'4_ZBB_Charges'!$D:$D,"Qualité")-SUMIFS('4_ZBB_Charges'!$G:$G,'4_ZBB_Charges'!$B:$B,"6131",'4_ZBB_Charges'!$D:$D,"Qualité"),0) -> 0 | F6: =IFERROR(SUMIFS('4_ZBB_Charges'!$H:$H,'4_ZBB_Charges'!$B:$B,"6131",'4_ZBB_Charges'!$D:$D,"Logistique")-SUMIFS('4_ZBB_Charges'!$G:$G,'4_ZBB_Charges'!$B:$B,"6131",'4_ZBB_Charges'!$D:$D,"Logistique"),0) -> 0 | G6: =IFERROR(SUMIFS('4_ZBB_Charges'!$H:$H,'4_ZBB_Charges'!$B:$B,"6131",'4_ZBB_Charges'!$D:$D,"Commercial")-SUMIFS('4_ZBB_Charges'!$G:$G,'4_ZBB_Charges'!$B:$B,"6131",'4_ZBB_Charges'!$D:$D,"Commercial"),0) -> 0 | H6: =IFERROR(SUMIFS('4_ZBB_Charges'!$H:$H,'4_ZBB_Charges'!$B:$B,"6131",'4_ZBB_Charges'!$D:$D,"Admin/Finance")-SUMIFS('4_ZBB_Charges'!$G:$G,'4_ZBB_Charges'!$B:$B,"6131",'4_ZBB_Charges'!$D:$D,"Admin/Finance"),0) -> 0 | I6: =SUM(C6:H6) -> 20000
B7: 6132 | C7: =IFERROR(SUMIFS('4_ZBB_Charges'!$H:$H,'4_ZBB_Charges'!$B:$B,"6132",'4_ZBB_Charges'!$D:$D,"Production")-SUMIFS('4_ZBB_Charges'!$G:$G,'4_ZBB_Charges'!$B:$B,"6132",'4_ZBB_Charges'!$D:$D,"Production"),0) -> 20000 | D7: =IFERROR(SUMIFS('4_ZBB_Charges'!$H:$H,'4_ZBB_Charges'!$B:$B,"6132",'4_ZBB_Charges'!$D:$D,"Maintenance")-SUMIFS('4_ZBB_Charges'!$G:$G,'4_ZBB_Charges'!$B:$B,"6132",'4_ZBB_Charges'!$D:$D,"Maintenance"),0) -> 0 | E7: =IFERROR(SUMIFS('4_ZBB_Charges'!$H:$H,'4_ZBB_Charges'!$B:$B,"6132",'4_ZBB_Charges'!$D:$D,"Qualité")-SUMIFS('4_ZBB_Charges'!$G:$G,'4_ZBB_Charges'!$B:$B,"6132",'4_ZBB_Charges'!$D:$D,"Qualité"),0) -> 0 | F7: =IFERROR(SUMIFS('4_ZBB_Charges'!$H:$H,'4_ZBB_Charges'!$B:$B,"6132",'4_ZBB_Charges'!$D:$D,"Logistique")-SUMIFS('4_ZBB_Charges'!$G:$G,'4_ZBB_Charges'!$B:$B,"6132",'4_ZBB_Charges'!$D:$D,"Logistique"),0) -> 30000 | G7: =IFERROR(SUMIFS('4_ZBB_Charges'!$H:$H,'4_ZBB_Charges'!$B:$B,"6132",'4_ZBB_Charges'!$D:$D,"Commercial")-SUMIFS('4_ZBB_Charges'!$G:$G,'4_ZBB_Charges'!$B:$B,"6132",'4_ZBB_Charges'!$D:$D,"Commercial"),0) -> 0 | H7: =IFERROR(SUMIFS('4_ZBB_Charges'!$H:$H,'4_ZBB_Charges'!$B:$B,"6132",'4_ZBB_Charges'!$D:$D,"Admin/Finance")-SUMIFS('4_ZBB_Charges'!$G:$G,'4_ZBB_Charges'!$B:$B,"6132",'4_ZBB_Charges'!$D:$D,"Admin/Finance"),0) -> 10000 | I7: =SUM(C7:H7) -> 60000
B8: 6133 | C8: =IFERROR(SUMIFS('4_ZBB_Charges'!$H:$H,'4_ZBB_Charges'!$B:$B,"6133",'4_ZBB_Charges'!$D:$D,"Production")-SUMIFS('4_ZBB_Charges'!$G:$G,'4_ZBB_Charges'!$B:$B,"6133",'4_ZBB_Charges'!$D:$D,"Production"),0) -> 0 | D8: =IFERROR(SUMIFS('4_ZBB_Charges'!$H:$H,'4_ZBB_Charges'!$B:$B,"6133",'4_ZBB_Charges'!$D:$D,"Maintenance")-SUMIFS('4_ZBB_Charges'!$G:$G,'4_ZBB_Charges'!$B:$B,"6133",'4_ZBB_Charges'!$D:$D,"Maintenance"),0) -> -15000 | E8: =IFERROR(SUMIFS('4_ZBB_Charges'!$H:$H,'4_ZBB_Charges'!$B:$B,"6133",'4_ZBB_Charges'!$D:$D,"Qualité")-SUMIFS('4_ZBB_Charges'!$G:$G,'4_ZBB_Charges'!$B:$B,"6133",'4_ZBB_Charges'!$D:$D,"Qualité"),0) -> 0 | F8: =IFERROR(SUMIFS('4_ZBB_Charges'!$H:$H,'4_ZBB_Charges'!$B:$B,"6133",'4_ZBB_Charges'!$D:$D,"Logistique")-SUMIFS('4_ZBB_Charges'!$G:$G,'4_ZBB_Charges'!$B:$B,"6133",'4_ZBB_Charges'!$D:$D,"Logistique"),0) -> 0 | G8: =IFERROR(SUMIFS('4_ZBB_Charges'!$H:$H,'4_ZBB_Charges'!$B:$B,"6133",'4_ZBB_Charges'!$D:$D,"Commercial")-SUMIFS('4_ZBB_Charges'!$G:$G,'4_ZBB_Charges'!$B:$B,"6133",'4_ZBB_Charges'!$D:$D,"Commercial"),0) -> 0 | H8: =IFERROR(SUMIFS('4_ZBB_Charges'!$H:$H,'4_ZBB_Charges'!$B:$B,"6133",'4_ZBB_Charges'!$D:$D,"Admin/Finance")-SUMIFS('4_ZBB_Charges'!$G:$G,'4_ZBB_Charges'!$B:$B,"6133",'4_ZBB_Charges'!$D:$D,"Admin/Finance"),0) -> 0 | I8: =SUM(C8:H8) -> -15000
B9: 6134 | C9: =IFERROR(SUMIFS('4_ZBB_Charges'!$H:$H,'4_ZBB_Charges'!$B:$B,"6134",'4_ZBB_Charges'!$D:$D,"Production")-SUMIFS('4_ZBB_Charges'!$G:$G,'4_ZBB_Charges'!$B:$B,"6134",'4_ZBB_Charges'!$D:$D,"Production"),0) -> 0 | D9: =IFERROR(SUMIFS('4_ZBB_Charges'!$H:$H,'4_ZBB_Charges'!$B:$B,"6134",'4_ZBB_Charges'!$D:$D,"Maintenance")-SUMIFS('4_ZBB_Charges'!$G:$G,'4_ZBB_Charges'!$B:$B,"6134",'4_ZBB_Charges'!$D:$D,"Maintenance"),0) -> 0 | E9: =IFERROR(SUMIFS('4_ZBB_Charges'!$H:$H,'4_ZBB_Charges'!$B:$B,"6134",'4_ZBB_Charges'!$D:$D,"Qualité")-SUMIFS('4_ZBB_Charges'!$G:$G,'4_ZBB_Charges'!$B:$B,"6134",'4_ZBB_Charges'!$D:$D,"Qualité"),0) -> 0 | F9: =IFERROR(SUMIFS('4_ZBB_Charges'!$H:$H,'4_ZBB_Charges'!$B:$B,"6134",'4_ZBB_Charges'!$D:$D,"Logistique")-SUMIFS('4_ZBB_Charges'!$G:$G,'4_ZBB_Charges'!$B:$B,"6134",'4_ZBB_Charges'!$D:$D,"Logistique"),0) -> 8000 | G9: =IFERROR(SUMIFS('4_ZBB_Charges'!$H:$H,'4_ZBB_Charges'!$B:$B,"6134",'4_ZBB_Charges'!$D:$D,"Commercial")-SUMIFS('4_ZBB_Charges'!$G:$G,'4_ZBB_Charges'!$B:$B,"6134",'4_ZBB_Charges'!$D:$D,"Commercial"),0) -> 0 | H9: =IFERROR(SUMIFS('4_ZBB_Charges'!$H:$H,'4_ZBB_Charges'!$B:$B,"6134",'4_ZBB_Charges'!$D:$D,"Admin/Finance")-SUMIFS('4_ZBB_Charges'!$G:$G,'4_ZBB_Charges'!$B:$B,"6134",'4_ZBB_Charges'!$D:$D,"Admin/Finance"),0) -> 15000 | I9: =SUM(C9:H9) -> 23000
B10: 6135 | C10: =IFERROR(SUMIFS('4_ZBB_Charges'!$H:$H,'4_ZBB_Charges'!$B:$B,"6135",'4_ZBB_Charges'!$D:$D,"Production")-SUMIFS('4_ZBB_Charges'!$G:$G,'4_ZBB_Charges'!$B:$B,"6135",'4_ZBB_Charges'!$D:$D,"Production"),0) -> 0 | D10: =IFERROR(SUMIFS('4_ZBB_Charges'!$H:$H,'4_ZBB_Charges'!$B:$B,"6135",'4_ZBB_Charges'!$D:$D,"Maintenance")-SUMIFS('4_ZBB_Charges'!$G:$G,'4_ZBB_Charges'!$B:$B,"6135",'4_ZBB_Charges'!$D:$D,"Maintenance"),0) -> 0 | E10: =IFERROR(SUMIFS('4_ZBB_Charges'!$H:$H,'4_ZBB_Charges'!$B:$B,"6135",'4_ZBB_Charges'!$D:$D,"Qualité")-SUMIFS('4_ZBB_Charges'!$G:$G,'4_ZBB_Charges'!$B:$B,"6135",'4_ZBB_Charges'!$D:$D,"Qualité"),0) -> 0 | F10: =IFERROR(SUMIFS('4_ZBB_Charges'!$H:$H,'4_ZBB_Charges'!$B:$B,"6135",'4_ZBB_Charges'!$D:$D,"Logistique")-SUMIFS('4_ZBB_Charges'!$G:$G,'4_ZBB_Charges'!$B:$B,"6135",'4_ZBB_Charges'!$D:$D,"Logistique"),0) -> 0 | G10: =IFERROR(SUMIFS('4_ZBB_Charges'!$H:$H,'4_ZBB_Charges'!$B:$B,"6135",'4_ZBB_Charges'!$D:$D,"Commercial")-SUMIFS('4_ZBB_Charges'!$G:$G,'4_ZBB_Charges'!$B:$B,"6135",'4_ZBB_Charges'!$D:$D,"Commercial"),0) -> 25000 | H10: =IFERROR(SUMIFS('4_ZBB_Charges'!$H:$H,'4_ZBB_Charges'!$B:$B,"6135",'4_ZBB_Charges'!$D:$D,"Admin/Finance")-SUMIFS('4_ZBB_Charges'!$G:$G,'4_ZBB_Charges'!$B:$B,"6135",'4_ZBB_Charges'!$D:$D,"Admin/Finance"),0) -> 0 | I10: =SUM(C10:H10) -> 25000
B11: 6136 | C11: =IFERROR(SUMIFS('4_ZBB_Charges'!$H:$H,'4_ZBB_Charges'!$B:$B,"6136",'4_ZBB_Charges'!$D:$D,"Production")-SUMIFS('4_ZBB_Charges'!$G:$G,'4_ZBB_Charges'!$B:$B,"6136",'4_ZBB_Charges'!$D:$D,"Production"),0) -> 0 | D11: =IFERROR(SUMIFS('4_ZBB_Charges'!$H:$H,'4_ZBB_Charges'!$B:$B,"6136",'4_ZBB_Charges'!$D:$D,"Maintenance")-SUMIFS('4_ZBB_Charges'!$G:$G,'4_ZBB_Charges'!$B:$B,"6136",'4_ZBB_Charges'!$D:$D,"Maintenance"),0) -> 0 | E11: =IFERROR(SUMIFS('4_ZBB_Charges'!$H:$H,'4_ZBB_Charges'!$B:$B,"6136",'4_ZBB_Charges'!$D:$D,"Qualité")-SUMIFS('4_ZBB_Charges'!$G:$G,'4_ZBB_Charges'!$B:$B,"6136",'4_ZBB_Charges'!$D:$D,"Qualité"),0) -> 0 | F11: =IFERROR(SUMIFS('4_ZBB_Charges'!$H:$H,'4_ZBB_Charges'!$B:$B,"6136",'4_ZBB_Charges'!$D:$D,"Logistique")-SUMIFS('4_ZBB_Charges'!$G:$G,'4_ZBB_Charges'!$B:$B,"6136",'4_ZBB_Charges'!$D:$D,"Logistique"),0) -> 0 | G11: =IFERROR(SUMIFS('4_ZBB_Charges'!$H:$H,'4_ZBB_Charges'!$B:$B,"6136",'4_ZBB_Charges'!$D:$D,"Commercial")-SUMIFS('4_ZBB_Charges'!$G:$G,'4_ZBB_Charges'!$B:$B,"6136",'4_ZBB_Charges'!$D:$D,"Commercial"),0) -> 0 | H11: =IFERROR(SUMIFS('4_ZBB_Charges'!$H:$H,'4_ZBB_Charges'!$B:$B,"6136",'4_ZBB_Charges'!$D:$D,"Admin/Finance")-SUMIFS('4_ZBB_Charges'!$G:$G,'4_ZBB_Charges'!$B:$B,"6136",'4_ZBB_Charges'!$D:$D,"Admin/Finance"),0) -> 17000 | I11: =SUM(C11:H11) -> 17000
B12: 6137 | C12: =IFERROR(SUMIFS('4_ZBB_Charges'!$H:$H,'4_ZBB_Charges'!$B:$B,"6137",'4_ZBB_Charges'!$D:$D,"Production")-SUMIFS('4_ZBB_Charges'!$G:$G,'4_ZBB_Charges'!$B:$B,"6137",'4_ZBB_Charges'!$D:$D,"Production"),0) -> 0 | D12: =IFERROR(SUMIFS('4_ZBB_Charges'!$H:$H,'4_ZBB_Charges'!$B:$B,"6137",'4_ZBB_Charges'!$D:$D,"Maintenance")-SUMIFS('4_ZBB_Charges'!$G:$G,'4_ZBB_Charges'!$B:$B,"6137",'4_ZBB_Charges'!$D:$D,"Maintenance"),0) -> 0 | E12: =IFERROR(SUMIFS('4_ZBB_Charges'!$H:$H,'4_ZBB_Charges'!$B:$B,"6137",'4_ZBB_Charges'!$D:$D,"Qualité")-SUMIFS('4_ZBB_Charges'!$G:$G,'4_ZBB_Charges'!$B:$B,"6137",'4_ZBB_Charges'!$D:$D,"Qualité"),0) -> 0 | F12: =IFERROR(SUMIFS('4_ZBB_Charges'!$H:$H,'4_ZBB_Charges'!$B:$B,"6137",'4_ZBB_Charges'!$D:$D,"Logistique")-SUMIFS('4_ZBB_Charges'!$G:$G,'4_ZBB_Charges'!$B:$B,"6137",'4_ZBB_Charges'!$D:$D,"Logistique"),0) -> 0 | G12: =IFERROR(SUMIFS('4_ZBB_Charges'!$H:$H,'4_ZBB_Charges'!$B:$B,"6137",'4_ZBB_Charges'!$D:$D,"Commercial")-SUMIFS('4_ZBB_Charges'!$G:$G,'4_ZBB_Charges'!$B:$B,"6137",'4_ZBB_Charges'!$D:$D,"Commercial"),0) -> 15000 | H12: =IFERROR(SUMIFS('4_ZBB_Charges'!$H:$H,'4_ZBB_Charges'!$B:$B,"6137",'4_ZBB_Charges'!$D:$D,"Admin/Finance")-SUMIFS('4_ZBB_Charges'!$G:$G,'4_ZBB_Charges'!$B:$B,"6137",'4_ZBB_Charges'!$D:$D,"Admin/Finance"),0) -> 0 | I12: =SUM(C12:H12) -> 15000
B13: 6142 | C13: =IFERROR(SUMIFS('4_ZBB_Charges'!$H:$H,'4_ZBB_Charges'!$B:$B,"6142",'4_ZBB_Charges'!$D:$D,"Production")-SUMIFS('4_ZBB_Charges'!$G:$G,'4_ZBB_Charges'!$B:$B,"6142",'4_ZBB_Charges'!$D:$D,"Production"),0) -> 0 | D13: =IFERROR(SUMIFS('4_ZBB_Charges'!$H:$H,'4_ZBB_Charges'!$B:$B,"6142",'4_ZBB_Charges'!$D:$D,"Maintenance")-SUMIFS('4_ZBB_Charges'!$G:$G,'4_ZBB_Charges'!$B:$B,"6142",'4_ZBB_Charges'!$D:$D,"Maintenance"),0) -> 0 | E13: =IFERROR(SUMIFS('4_ZBB_Charges'!$H:$H,'4_ZBB_Charges'!$B:$B,"6142",'4_ZBB_Charges'!$D:$D,"Qualité")-SUMIFS('4_ZBB_Charges'!$G:$G,'4_ZBB_Charges'!$B:$B,"6142",'4_ZBB_Charges'!$D:$D,"Qualité"),0) -> 0 | F13: =IFERROR(SUMIFS('4_ZBB_Charges'!$H:$H,'4_ZBB_Charges'!$B:$B,"6142",'4_ZBB_Charges'!$D:$D,"Logistique")-SUMIFS('4_ZBB_Charges'!$G:$G,'4_ZBB_Charges'!$B:$B,"6142",'4_ZBB_Charges'!$D:$D,"Logistique"),0) -> 55000 | G13: =IFERROR(SUMIFS('4_ZBB_Charges'!$H:$H,'4_ZBB_Charges'!$B:$B,"6142",'4_ZBB_Charges'!$D:$D,"Commercial")-SUMIFS('4_ZBB_Charges'!$G:$G,'4_ZBB_Charges'!$B:$B,"6142",'4_ZBB_Charges'!$D:$D,"Commercial"),0) -> 0 | H13: =IFERROR(SUMIFS('4_ZBB_Charges'!$H:$H,'4_ZBB_Charges'!$B:$B,"6142",'4_ZBB_Charges'!$D:$D,"Admin/Finance")-SUMIFS('4_ZBB_Charges'!$G:$G,'4_ZBB_Charges'!$B:$B,"6142",'4_ZBB_Charges'!$D:$D,"Admin/Finance"),0) -> 0 | I13: =SUM(C13:H13) -> 55000
